Workbook

Sheet 💼 Pipeline
A1: 💼 TRULANDER JSF LIMITED — SALES PIPELINE | ROYAL PALM ENCLAVE
A2: Blue cells = enter data freely · Black auto-calc cells = formula locked · Discount ✎ = formula but can be overridden · pw: JSF2026
A4: TOTAL LEADS | C4: GRAND TOTAL | E4: COLLECTED | G4: OUTSTANDING | I4: INTEREST TOTAL | K4: SITE VISITS | M4: HIGH PRIORITY | O4: PLOT UNITS | Q4: VS TARGET
A5: =COUNTA(B8:B100) -> 9 | C5: =IFERROR(SUM(N8:N100),0) -> 694500 | E5: =IFERROR(SUM(Q8:Q100),0) -> 0 | G5: =IFERROR(SUM(R8:R100),0) -> 694500 | I5: =IFERROR(SUM(M8:M100),0) -> 34500 | K5: =COUNTIF(O8:O100,"Yes") -> 2 | M5: =COUNTIF(P8:P100,"High") -> 1 | O5: =IFERROR(SUMIF(F8:F100,"Full Plot",G8:G100)+SUMIF(F8:F100,"Half Plot",G8:G100)/2,0) -> 15.75 | Q5: =IFERROR(SUM(Q8:Q100)/'⚙️ Config'!$B$19,0) -> 0
A6: # | C6: GHS | E6: GHS | G6: GHS | I6: GHS | K6: done | M6: urgent | O6: units | Q6: achieved
A7: # | B7: Lead Name | C7: Contact | D7: Date Added | E7: Stage | F7: Plot Type | G7: No. Plots | H7: Unit Price (GHS) | I7: Gross Total (GHS) | J7: Discount (GHS) ✎ | K7: Net Total (GHS) | L7: Payment Plan | M7: Interest (GHS) | N7: Grand Total (GHS) | O7: Site Visit | P7: Priority | Q7: Amt Paid (GHS) | R7: Balance (GHS) | S7: Next Action | T7: Notes
A8: =IF($B8="","",ROW()-7) -> 1 | B8: Ps Charles | C8: 0277966499 | D8: 46127 | E8: Negotiation | F8: Full Plot | G8: 2 | H8: =IF($B8="","",IF($F8="Full Plot",'⚙️ Config'!$B$6,IF($F8="Half Plot",'⚙️ Config'!$B$7,""))) -> 48000 | I8: =IF($B8="","",IF($F8="Full Plot",$G8*'⚙️ Config'!$B$6,IF($F8="Half Plot",($G8/'⚙️ Config'!$E$7)*'⚙️ Config'!$B$7,0))) -> 96000 | J8: =IF($B8="","",IF($F8="Full Plot",$G8*'⚙️ Config'!$C$6,IF($F8="Half Plot",($G8/'⚙️ Config'!$E$7)*'⚙️ Config'!$C$7,0))) -> 16000 | K8: =IF($B8="","",IFERROR($I8-$J8,0)) -> 80000 | L8: 6 Months | M8: =IF($B8="","",IF($L8="","",IF($F8="Full Plot",$G8,IF($F8="Half Plot",$G8/'⚙️ Config'!$E$7,0))*IFERROR(VLOOKUP($L8,'⚙️ Config'!$A$11:$B$14,2,0),0))) -> 3000 | N8: =IF($B8="","",IFERROR($K8+IF($M8="",$K8*0,$M8),0)) -> 83000 | O8: Yes | P8: Medium | R8: =IF($B8="","",IFERROR(MAX($N8-$Q8,0),0)) -> 83000 | S8: Follow up with calls to check up | T8: Just had some emergencies come up so wants to focus on dealing with them first. Will certainly make a purchase
A9: =IF($B9="","",ROW()-7) -> 2 | B9: Mad. Elizabeth Annor | C9: +1(856)745-9802 | D9: 46134 | E9: Qualified | F9: Full Plot | G9: 6 | H9: =IF($B9="","",IF($F9="Full Plot",'⚙️ Config'!$B$6,IF($F9="Half Plot",'⚙️ Config'!$B$7,""))) -> 48000 | I9: =IF($B9="","",IF($F9="Full Plot",$G9*'⚙️ Config'!$B$6,IF($F9="Half Plot",($G9/'⚙️ Config'!$E$7)*'⚙️ Config'!$B$7,0))) -> 288000 | J9: =IF($B9="","",IF($F9="Full Plot",$G9*'⚙️ Config'!$C$6,IF($F9="Half Plot",($G9/'⚙️ Config'!$E$7)*'⚙️ Config'!$C$7,0))) -> 48000 | K9: =IF($B9="","",IFERROR($I9-$J9,0)) -> 240000 | L9: 12 Months | M9: =IF($B9="","",IF($L9="","",IF($F9="Full Plot",$G9,IF($F9="Half Plot",$G9/'⚙️ Config'!$E$7,0))*IFERROR(VLOOKUP($L9,'⚙️ Config'!$A$11:$B$14,2,0),0))) -> 18000 | N9: =IF($B9="","",IFERROR($K9+IF($M9="",$K9*0,$M9),0)) -> 258000 | O9: Yes | P9: High | R9: =IF($B9="","",IFERROR(MAX($N9-$Q9,0),0)) -> 258000 | S9: Follow up with payments | T9: Wants to pay 20000gh as deposit and will pay 10000gh each month after the deposit
A10: =IF($B10="","",ROW()-7) -> 3 | B10: Dcns Nyamekye | C10: 0541157374 | D10: 46132 | E10: Negotiation | F10: Full Plot | G10: 1 | H10: =IF($B10="","",IF($F10="Full Plot",'⚙️ Config'!$B$6,IF($F10="Half Plot",'⚙️ Config'!$B$7,""))) -> 48000 | I10: =IF($B10="","",IF($F10="Full Plot",$G10*'⚙️ Config'!$B$6,IF($F10="Half Plot",($G10/'⚙️ Config'!$E$7)*'⚙️ Config'!$B$7,0))) -> 48000 | J10: =IF($B10="","",IF($F10="Full Plot",$G10*'⚙️ Config'!$C$6,IF($F10="Half Plot",($G10/'⚙️ Config'!$E$7)*'⚙️ Config'!$C$7,0))) -> 8000 | K10: =IF($B10="","",IFERROR($I10-$J10,0)) -> 40000 | L10: 6 Months | M10: =IF($B10="","",IF($L10="","",IF($F10="Full Plot",$G10,IF($F10="Half Plot",$G10/'⚙️ Config'!$E$7,0))*IFERROR(VLOOKUP($L10,'⚙️ Config'!$A$11:$B$14,2,0),0))) -> 1500 | N10: =IF($B10="","",IFERROR($K10+IF($M10="",$K10*0,$M10),0)) -> 41500 | O10: No | P10: Medium | R10: =IF($B10="","",IFERROR(MAX($N10-$Q10,0),0)) -> 41500 | S10: Follow up with calls to check up | T10: Wants to put purchasing the land on a hold till June
A11: =IF($B11="","",ROW()-7) -> 4 | B11: David Ocran | C11: 0205648880 | D11: 46096 | E11: Negotiation | F11: Half Plot | G11: 0.5 | H11: =IF($B11="","",IF($F11="Full Plot",'⚙️ Config'!$B$6,IF($F11="Half Plot",'⚙️ Config'!$B$7,""))) -> 26500 | I11: =IF($B11="","",IF($F11="Full Plot",$G11*'⚙️ Config'!$B$6,IF($F11="Half Plot",($G11/'⚙️ Config'!$E$7)*'⚙️ Config'!$B$7,0))) -> 26500 | J11: =IF($B11="","",IF($F11="Full Plot",$G11*'⚙️ Config'!$C$6,IF($F11="Half Plot",($G11/'⚙️ Config'!$E$7)*'⚙️ Config'!$C$7,0))) -> 6500 | K11: =IF($B11="","",IFERROR($I11-$J11,0)) -> 20000 | L11: 6 Months | M11: =IF($B11="","",IF($L11="","",IF($F11="Full Plot",$G11,IF($F11="Half Plot",$G11/'⚙️ Config'!$E$7,0))*IFERROR(VLOOKUP($L11,'⚙️ Config'!$A$11:$B$14,2,0),0))) -> 1500 | N11: =IF($B11="","",IFERROR($K11+IF($M11="",$K11*0,$M11),0)) -> 21500 | O11: No | P11: Medium | R11: =IF($B11="","",IFERROR(MAX($N11-$Q11,0),0)) -> 21500 | S11: Follow up with calls to check on mom and work | T11: Wants me to engage him again in June
A12: =IF($B12="","",ROW()-7) -> 5 | B12: Ruby Offerie | C12: +1(217)790-9464 | D12: 46006 | E12: Prospecting | F12: Full Plot | G12: 1 | H12: =IF($B12="","",IF($F12="Full Plot",'⚙️ Config'!$B$6,IF($F12="Half Plot",'⚙️ Config'!$B$7,""))) -> 48000 | I12: =IF($B12="","",IF($F12="Full Plot",$G12*'⚙️ Config'!$B$6,IF($F12="Half Plot",($G12/'⚙️ Config'!$E$7)*'⚙️ Config'!$B$7,0))) -> 48000 | J12: =IF($B12="","",IF($F12="Full Plot",$G12*'⚙️ Config'!$C$6,IF($F12="Half Plot",($G12/'⚙️ Config'!$E$7)*'⚙️ Config'!$C$7,0))) -> 8000 | K12: =IF($B12="","",IFERROR($I12-$J12,0)) -> 40000 | L12: 6 Months | M12: =IF($B12="","",IF($L12="","",IF($F12="Full Plot",$G12,IF($F12="Half Plot",$G12/'⚙️ Config'!$E$7,0))*IFERROR(VLOOKUP($L12,'⚙️ Config'!$A$11:$B$14,2,0),0))) -> 1500 | N12: =IF($B12="","",IFERROR($K12+IF($M12="",$K12*0,$M12),0)) -> 41500 | O12: No | P12: Low | R12: =IF($B12="","",IFERROR(MAX($N12-$Q12,0),0)) -> 41500 | S12: Follow up with texts concerning colleagues contacts she promised to give | T12: Says she has spoken to colleagues and shown them her indentures but for some time now they have not been answering her calls. She showed her chats with them and promised to continue with follow ups before I can engage them
A13: =IF($B13="","",ROW()-7) -> 6 | B13: Gideon | C13: 0554499386 | D13: 46109 | E13: Discovery | F13: Full Plot | G13: 2 | H13: =IF($B13="","",IF($F13="Full Plot",'⚙️ Config'!$B$6,IF($F13="Half Plot",'⚙️ Config'!$B$7,""))) -> 48000 | I13: =IF($B13="","",IF($F13="Full Plot",$G13*'⚙️ Config'!$B$6,IF($F13="Half Plot",($G13/'⚙️ Config'!$E$7)*'⚙️ Config'!$B$7,0))) -> 96000 | J13: =IF($B13="","",IF($F13="Full Plot",$G13*'⚙️ Config'!$C$6,IF($F13="Half Plot",($G13/'⚙️ Config'!$E$7)*'⚙️ Config'!$C$7,0))) -> 16000 | K13: =IF($B13="","",IFERROR($I13-$J13,0)) -> 80000 | L13: 6 Months | M13: =IF($B13="","",IF($L13="","",IF($F13="Full Plot",$G13,IF($F13="Half Plot",$G13/'⚙️ Config'!$E$7,0))*IFERROR(VLOOKUP($L13,'⚙️ Config'!$A$11:$B$14,2,0),0))) -> 3000 | N13: =IF($B13="","",IFERROR($K13+IF($M13="",$K13*0,$M13),0)) -> 83000 | O13: No | P13: Low | R13: =IF($B13="","",IFERROR(MAX($N13-$Q13,0),0)) -> 83000 | S13: Follow up with texts and calls concerning feedback from friend | T13: His friemd is the one interested. Initially he complained Tsopoli was far and would prefer Oyibi. After engagement on benefits of Tsopoli over Oyibi he wants time to convince the friend to buy from us
A14: =IF($B14="","",ROW()-7) -> 7 | B14: Joshua Ameworwor | C14: +1(720)276-9656 | D14: 46099 | E14: Discovery | F14: Full Plot | G14: 2 | H14: =IF($B14="","",IF($F14="Full Plot",'⚙️ Config'!$B$6,IF($F14="Half Plot",'⚙️ Config'!$B$7,""))) -> 48000 | I14: =IF($B14="","",IF($F14="Full Plot",$G14*'⚙️ Config'!$B$6,IF($F14="Half Plot",($G14/'⚙️ Config'!$E$7)*'⚙️ Config'!$B$7,0))) -> 96000 | J14: =IF($B14="","",IF($F14="Full Plot",$G14*'⚙️ Config'!$C$6,IF($F14="Half Plot",($G14/'⚙️ Config'!$E$7)*'⚙️ Config'!$C$7,0))) -> 16000 | K14: =IF($B14="","",IFERROR($I14-$J14,0)) -> 80000 | L14: 3 Months | M14: =IF($B14="","",IF($L14="","",IF($F14="Full Plot",$G14,IF($F14="Half Plot",$G14/'⚙️ Config'!$E$7,0))*IFERROR(VLOOKUP($L14,'⚙️ Config'!$A$11:$B$14,2,0),0))) -> 1500 | N14: =IF($B14="","",IFERROR($K14+IF($M14="",$K14*0,$M14),0)) -> 81500 | O14: No | P14: Low | R14: =IF($B14="","",IFERROR(MAX($N14-$Q14,0),0)) -> 81500 | S14: Follow up with calls and texts to cehck up on dad and him | T14: Just made payments for his dad's surgery so is down with cash. He says I should give him a month to gather money to pay outrightly for all two plots
A15: =IF($B15="","",ROW()-7) -> 8 | B15: Yaa Sweetie | C15: +1(908)759-3710 | D15: 46101 | E15: Negotiation | F15: Half Plot | G15: 1 | H15: =IF($B15="","",IF($F15="Full Plot",'⚙️ Config'!$B$6,IF($F15="Half Plot",'⚙️ Config'!$B$7,""))) -> 26500 | I15: =IF($B15="","",IF($F15="Full Plot",$G15*'⚙️ Config'!$B$6,IF($F15="Half Plot",($G15/'⚙️ Config'!$E$7)*'⚙️ Config'!$B$7,0))) -> 53000 | J15: =IF($B15="","",IF($F15="Full Plot",$G15*'⚙️ Config'!$C$6,IF($F15="Half Plot",($G15/'⚙️ Config'!$E$7)*'⚙️ Config'!$C$7,0))) -> 13000 | K15: =IF($B15="","",IFERROR($I15-$J15,0)) -> 40000 | L15: 3 Months | M15: =IF($B15="","",IF($L15="","",IF($F15="Full Plot",$G15,IF($F15="Half Plot",$G15/'⚙️ Config'!$E$7,0))*IFERROR(VLOOKUP($L15,'⚙️ Config'!$A$11:$B$14,2,0),0))) -> 1500 | N15: =IF($B15="","",IFERROR($K15+IF($M15="",$K15*0,$M15),0)) -> 41500 | O15: No | P15: Medium | R15: =IF($B15="","",IFERROR(MAX($N15-$Q15,0),0)) -> 41500 | S15: Wants to engage her husband on the discussion had | T15: Will alert me on any feedback from the discussion with her husband
A16: =IF($B16="","",ROW()-7) -> 9 | B16: Mr Antwi | C16: 0539899658 | D16: 46103 | E16: Prospecting | F16: Full Plot | G16: 1 | H16: =IF($B16="","",IF($F16="Full Plot",'⚙️ Config'!$B$6,IF($F16="Half Plot",'⚙️ Config'!$B$7,""))) -> 48000 | I16: =IF($B16="","",IF($F16="Full Plot",$G16*'⚙️ Config'!$B$6,IF($F16="Half Plot",($G16/'⚙️ Config'!$E$7)*'⚙️ Config'!$B$7,0))) -> 48000 | J16: =IF($B16="","",IF($F16="Full Plot",$G16*'⚙️ Config'!$C$6,IF($F16="Half Plot",($G16/'⚙️ Config'!$E$7)*'⚙️ Config'!$C$7,0))) -> 8000 | K16: =IF($B16="","",IFERROR($I16-$J16,0)) -> 40000 | L16: 12 Months | M16: =IF($B16="","",IF($L16="","",IF($F16="Full Plot",$G16,IF($F16="Half Plot",$G16/'⚙️ Config'!$E$7,0))*IFERROR(VLOOKUP($L16,'⚙️ Config'!$A$11:$B$14,2,0),0))) -> 3000 | N16: =IF($B16="","",IFERROR($K16+IF($M16="",$K16*0,$M16),0)) -> 43000 | O16: No | P16: Medium | R16: =IF($B16="","",IFERROR(MAX($N16-$Q16,0),0)) -> 43000 | S16: Follow up with texts and calls | T16: They relocated to Canada recently and want to settle down before they can make a purchase. Says I should start engaging him ending of May
A17: =IF($B17="","",ROW()-7) | H17: =IF($B17="","",IF($F17="Full Plot",'⚙️ Config'!$B$6,IF($F17="Half Plot",'⚙️ Config'!$B$7,""))) | I17: =IF($B17="","",IF($F17="Full Plot",$G17*'⚙️ Config'!$B$6,IF($F17="Half Plot",($G17/'⚙️ Config'!$E$7)*'⚙️ Config'!$B$7,0))) | J17: =IF($B17="","",IF($F17="Full Plot",$G17*'⚙️ Config'!$C$6,IF($F17="Half Plot",($G17/'⚙️ Config'!$E$7)*'⚙️ Config'!$C$7,0))) | K17: =IF($B17="","",IFERROR($I17-$J17,0)) | M17: =IF($B17="","",IF($L17="","",IF($F17="Full Plot",$G17,IF($F17="Half Plot",$G17/'⚙️ Config'!$E$7,0))*IFERROR(VLOOKUP($L17,'⚙️ Config'!$A$11:$B$14,2,0),0))) | N17: =IF($B17="","",IFERROR($K17+IF($M17="",$K17*0,$M17),0)) | R17: =IF($B17="","",IFERROR(MAX($N17-$Q17,0),0))
A18: =IF($B18="","",ROW()-7) | H18: =IF($B18="","",IF($F18="Full Plot",'⚙️ Config'!$B$6,IF($F18="Half Plot",'⚙️ Config'!$B$7,""))) | I18: =IF($B18="","",IF($F18="Full Plot",$G18*'⚙️ Config'!$B$6,IF($F18="Half Plot",($G18/'⚙️ Config'!$E$7)*'⚙️ Config'!$B$7,0))) | J18: =IF($B18="","",IF($F18="Full Plot",$G18*'⚙️ Config'!$C$6,IF($F18="Half Plot",($G18/'⚙️ Config'!$E$7)*'⚙️ Config'!$C$7,0))) | K18: =IF($B18="","",IFERROR($I18-$J18,0)) | N18: =IF($B18="","",IFERROR($K18+IF($M18="",$K18*0,$M18),0)) | R18: =IF($B18="","",IFERROR(MAX($N18-$Q18,0),0))
A19: =IF($B19="","",ROW()-7) | H19: =IF($B19="","",IF($F19="Full Plot",'⚙️ Config'!$B$6,IF($F19="Half Plot",'⚙️ Config'!$B$7,""))) | I19: =IF($B19="","",IF($F19="Full Plot",$G19*'⚙️ Config'!$B$6,IF($F19="Half Plot",($G19/'⚙️ Config'!$E$7)*'⚙️ Config'!$B$7,0))) | J19: =IF($B19="","",IF($F19="Full Plot",$G19*'⚙️ Config'!$C$6,IF($F19="Half Plot",($G19/'⚙️ Config'!$E$7)*'⚙️ Config'!$C$7,0))) | K19: =IF($B19="","",IFERROR($I19-$J19,0)) | M19: =IF($B19="","",IF($L19="","",IF($F19="Full Plot",$G19,IF($F19="Half Plot",$G19/'⚙️ Config'!$E$7,0))*IFERROR(VLOOKUP($L19,'⚙️ Config'!$A$11:$B$14,2,0),0))) | N19: =IF($B19="","",IFERROR($K19+IF($M19="",$K19*0,$M19),0)) | R19: =IF($B19="","",IFERROR(MAX($N19-$Q19,0),0))
A20: =IF($B20="","",ROW()-7) | H20: =IF($B20="","",IF($F20="Full Plot",'⚙️ Config'!$B$6,IF($F20="Half Plot",'⚙️ Config'!$B$7,""))) | I20: =IF($B20="","",IF($F20="Full Plot",$G20*'⚙️ Config'!$B$6,IF($F20="Half Plot",($G20/'⚙️ Config'!$E$7)*'⚙️ Config'!$B$7,0))) | J20: =IF($B20="","",IF($F20="Full Plot",$G20*'⚙️ Config'!$C$6,IF($F20="Half Plot",($G20/'⚙️ Config'!$E$7)*'⚙️ Config'!$C$7,0))) | K20: =IF($B20="","",IFERROR($I20-$J20,0)) | M20: =IF($B20="","",IF($L20="","",IF($F20="Full Plot",$G20,IF($F20="Half Plot",$G20/'⚙️ Config'!$E$7,0))*IFERROR(VLOOKUP($L20,'⚙️ Config'!$A$11:$B$14,2,0),0))) | N20: =IF($B20="","",IFERROR($K20+IF($M20="",$K20*0,$M20),0)) | R20: =IF($B20="","",IFERROR(MAX($N20-$Q20,0),0))
A21: =IF($B21="","",ROW()-7) | H21: =IF($B21="","",IF($F21="Full Plot",'⚙️ Config'!$B$6,IF($F21="Half Plot",'⚙️ Config'!$B$7,""))) | I21: =IF($B21="","",IF($F21="Full Plot",$G21*'⚙️ Config'!$B$6,IF($F21="Half Plot",($G21/'⚙️ Config'!$E$7)*'⚙️ Config'!$B$7,0))) | J21: =IF($B21="","",IF($F21="Full Plot",$G21*'⚙️ Config'!$C$6,IF($F21="Half Plot",($G21/'⚙️ Config'!$E$7)*'⚙️ Config'!$C$7,0))) | K21: =IF($B21="","",IFERROR($I21-$J21,0)) | M21: =IF($B21="","",IF($L21="","",IF($F21="Full Plot",$G21,IF($F21="Half Plot",$G21/'⚙️ Config'!$E$7,0))*IFERROR(VLOOKUP($L21,'⚙️ Config'!$A$11:$B$14,2,0),0))) | N21: =IF($B21="","",IFERROR($K21+IF($M21="",$K21*0,$M21),0)) | R21: =IF($B21="","",IFERROR(MAX($N21-$Q21,0),0))
A22: =IF($B22="","",ROW()-7) | H22: =IF($B22="","",IF($F22="Full Plot",'⚙️ Config'!$B$6,IF($F22="Half Plot",'⚙️ Config'!$B$7,""))) | I22: =IF($B22="","",IF($F22="Full Plot",$G22*'⚙️ Config'!$B$6,IF($F22="Half Plot",($G22/'⚙️ Config'!$E$7)*'⚙️ Config'!$B$7,0))) | J22: =IF($B22="","",IF($F22="Full Plot",$G22*'⚙️ Config'!$C$6,IF($F22="Half Plot",($G22/'⚙️ Config'!$E$7)*'⚙️ Config'!$C$7,0))) | K22: =IF($B22="","",IFERROR($I22-$J22,0)) | M22: =IF($B22="","",IF($L22="","",IF($F22="Full Plot",$G22,IF($F22="Half Plot",$G22/'⚙️ Config'!$E$7,0))*IFERROR(VLOOKUP($L22,'⚙️ Config'!$A$11:$B$14,2,0),0))) | N22: =IF($B22="","",IFERROR($K22+IF($M22="",$K22*0,$M22),0)) | R22: =IF($B22="","",IFERROR(MAX($N22-$Q22,0),0))
A23: =IF($B23="","",ROW()-7) | H23: =IF($B23="","",IF($F23="Full Plot",'⚙️ Config'!$B$6,IF($F23="Half Plot",'⚙️ Config'!$B$7,""))) | I23: =IF($B23="","",IF($F23="Full Plot",$G23*'⚙️ Config'!$B$6,IF($F23="Half Plot",($G23/'⚙️ Config'!$E$7)*'⚙️ Config'!$B$7,0))) | J23: =IF($B23="","",IF($F23="Full Plot",$G23*'⚙️ Config'!$C$6,IF($F23="Half Plot",($G23/'⚙️ Config'!$E$7)*'⚙️ Config'!$C$7,0))) | K23: =IF($B23="","",IFERROR($I23-$J23,0)) | M23: =IF($B23="","",IF($L23="","",IF($F23="Full Plot",$G23,IF($F23="Half Plot",$G23/'⚙️ Config'!$E$7,0))*IFERROR(VLOOKUP($L23,'⚙️ Config'!$A$11:$B$14,2,0),0))) | N23: =IF($B23="","",IFERROR($K23+IF($M23="",$K23*0,$M23),0)) | R23: =IF($B23="","",IFERROR(MAX($N23-$Q23,0),0))
A24: =IF($B24="","",ROW()-7) | H24: =IF($B24="","",IF($F24="Full Plot",'⚙️ Config'!$B$6,IF($F24="Half Plot",'⚙️ Config'!$B$7,""))) | I24: =IF($B24="","",IF($F24="Full Plot",$G24*'⚙️ Config'!$B$6,IF($F24="Half Plot",($G24/'⚙️ Config'!$E$7)*'⚙️ Config'!$B$7,0))) | J24: =IF($B24="","",IF($F24="Full Plot",$G24*'⚙️ Config'!$C$6,IF($F24="Half Plot",($G24/'⚙️ Config'!$E$7)*'⚙️ Config'!$C$7,0))) | K24: =IF($B24="","",IFERROR($I24-$J24,0)) | M24: =IF($B24="","",IF($L24="","",IF($F24="Full Plot",$G24,IF($F24="Half Plot",$G24/'⚙️ Config'!$E$7,0))*IFERROR(VLOOKUP($L24,'⚙️ Config'!$A$11:$B$14,2,0),0))) | N24: =IF($B24="","",IFERROR($K24+IF($M24="",$K24*0,$M24),0)) | R24: =IF($B24="","",IFERROR(MAX($N24-$Q24,0),0))
A25: =IF($B25="","",ROW()-7) | H25: =IF($B25="","",IF($F25="Full Plot",'⚙️ Config'!$B$6,IF($F25="Half Plot",'⚙️ Config'!$B$7,""))) | I25: =IF($B25="","",IF($F25="Full Plot",$G25*'⚙️ Config'!$B$6,IF($F25="Half Plot",($G25/'⚙️ Config'!$E$7)*'⚙️ Config'!$B$7,0))) | J25: =IF($B25="","",IF($F25="Full Plot",$G25*'⚙️ Config'!$C$6,IF($F25="Half Plot",($G25/'⚙️ Config'!$E$7)*'⚙️ Config'!$C$7,0))) | K25: =IF($B25="","",IFERROR($I25-$J25,0)) | M25: =IF($B25="","",IF($L25="","",IF($F25="Full Plot",$G25,IF($F25="Half Plot",$G25/'⚙️ Config'!$E$7,0))*IFERROR(VLOOKUP($L25,'⚙️ Config'!$A$11:$B$14,2,0),0))) | N25: =IF($B25="","",IFERROR($K25+IF($M25="",$K25*0,$M25),0)) | R25: =IF($B25="","",IFERROR(MAX($N25-$Q25,0),0))
A26: =IF($B26="","",ROW()-7) | H26: =IF($B26="","",IF($F26="Full Plot",'⚙️ Config'!$B$6,IF($F26="Half Plot",'⚙️ Config'!$B$7,""))) | I26: =IF($B26="","",IF($F26="Full Plot",$G26*'⚙️ Config'!$B$6,IF($F26="Half Plot",($G26/'⚙️ Config'!$E$7)*'⚙️ Config'!$B$7,0))) | J26: =IF($B26="","",IF($F26="Full Plot",$G26*'⚙️ Config'!$C$6,IF($F26="Half Plot",($G26/'⚙️ Config'!$E$7)*'⚙️ Config'!$C$7,0))) | K26: =IF($B26="","",IFERROR($I26-$J26,0)) | M26: =IF($B26="","",IF($L26="","",IF($F26="Full Plot",$G26,IF($F26="Half Plot",$G26/'⚙️ Config'!$E$7,0))*IFERROR(VLOOKUP($L26,'⚙️ Config'!$A$11:$B$14,2,0),0))) | N26: =IF($B26="","",IFERROR($K26+IF($M26="",$K26*0,$M26),0)) | R26: =IF($B26="","",IFERROR(MAX($N26-$Q26,0),0))
A27: =IF($B27="","",ROW()-7) | H27: =IF($B27="","",IF($F27="Full Plot",'⚙️ Config'!$B$6,IF($F27="Half Plot",'⚙️ Config'!$B$7,""))) | I27: =IF($B27="","",IF($F27="Full Plot",$G27*'⚙️ Config'!$B$6,IF($F27="Half Plot",($G27/'⚙️ Config'!$E$7)*'⚙️ Config'!$B$7,0))) | J27: =IF($B27="","",IF($F27="Full Plot",$G27*'⚙️ Config'!$C$6,IF($F27="Half Plot",($G27/'⚙️ Config'!$E$7)*'⚙️ Config'!$C$7,0))) | K27: =IF($B27="","",IFERROR($I27-$J27,0)) | M27: =IF($B27="","",IF($L27="","",IF($F27="Full Plot",$G27,IF($F27="Half Plot",$G27/'⚙️ Config'!$E$7,0))*IFERROR(VLOOKUP($L27,'⚙️ Config'!$A$11:$B$14,2,0),0))) | N27: =IF($B27="","",IFERROR($K27+IF($M27="",$K27*0,$M27),0)) | R27: =IF($B27="","",IFERROR(MAX($N27-$Q27,0),0))
A28: =IF($B28="","",ROW()-7) | H28: =IF($B28="","",IF($F28="Full Plot",'⚙️ Config'!$B$6,IF($F28="Half Plot",'⚙️ Config'!$B$7,""))) | I28: =IF($B28="","",IF($F28="Full Plot",$G28*'⚙️ Config'!$B$6,IF($F28="Half Plot",($G28/'⚙️ Config'!$E$7)*'⚙️ Config'!$B$7,0))) | J28: =IF($B28="","",IF($F28="Full Plot",$G28*'⚙️ Config'!$C$6,IF($F28="Half Plot",($G28/'⚙️ Config'!$E$7)*'⚙️ Config'!$C$7,0))) | K28: =IF($B28="","",IFERROR($I28-$J28,0)) | M28: =IF($B28="","",IF($L28="","",IF($F28="Full Plot",$G28,IF($F28="Half Plot",$G28/'⚙️ Config'!$E$7,0))*IFERROR(VLOOKUP($L28,'⚙️ Config'!$A$11:$B$14,2,0),0))) | N28: =IF($B28="","",IFERROR($K28+IF($M28="",$K28*0,$M28),0)) | R28: =IF($B28="","",IFERROR(MAX($N28-$Q28,0),0))
A29: ➕ ADD NEW CLIENT BELOW — Type name in column B, fill left to right · All formulas activate automatically
A30: =IF($B30="","",ROW()-7) | H30: =IF($B30="","",IF($F30="Full Plot",'⚙️ Config'!$B$6,IF($F30="Half Plot",'⚙️ Config'!$B$7,""))) | I30: =IF($B30="","",IF($F30="Full Plot",$G30*'⚙️ Config'!$B$6,IF($F30="Half Plot",($G30/'⚙️ Config'!$E$7)*'⚙️ Config'!$B$7,0))) | J30: =IF($B30="","",IF($F30="Full Plot",$G30*'⚙️ Config'!$C$6,IF($F30="Half Plot",($G30/'⚙️ Config'!$E$7)*'⚙️ Config'!$C$7,0))) | K30: =IF($B30="","",IFERROR($I30-$J30,0)) | M30: =IF($B30="","",IF($L30="","",IF($F30="Full Plot",$G30,IF($F30="Half Plot",$G30/'⚙️ Config'!$E$7,0))*IFERROR(VLOOKUP($L30,'⚙️ Config'!$A$11:$B$14,2,0),0))) | N30: =IF($B30="","",IFERROR($K30+IF($M30="",$K30*0,$M30),0)) | R30: =IF($B30="","",IFERROR(MAX($N30-$Q30,0),0))
A31: =IF($B31="","",ROW()-7) | H31: =IF($B31="","",IF($F31="Full Plot",'⚙️ Config'!$B$6,IF($F31="Half Plot",'⚙️ Config'!$B$7,""))) | I31: =IF($B31="","",IF($F31="Full Plot",$G31*'⚙️ Config'!$B$6,IF($F31="Half Plot",($G31/'⚙️ Config'!$E$7)*'⚙️ Config'!$B$7,0))) | J31: =IF($B31="","",IF($F31="Full Plot",$G31*'⚙️ Config'!$C$6,IF($F31="Half Plot",($G31/'⚙️ Config'!$E$7)*'⚙️ Config'!$C$7,0))) | K31: =IF($B31="","",IFERROR($I31-$J31,0)) | M31: =IF($B31="","",IF($L31="","",IF($F31="Full Plot",$G31,IF($F31="Half Plot",$G31/'⚙️ Config'!$E$7,0))*IFERROR(VLOOKUP($L31,'⚙️ Config'!$A$11:$B$14,2,0),0))) | N31: =IF($B31="","",IFERROR($K31+IF($M31="",$K31*0,$M31),0)) | R31: =IF($B31="","",IFERROR(MAX($N31-$Q31,0),0))
A32: =IF($B32="","",ROW()-7) | H32: =IF($B32="","",IF($F32="Full Plot",'⚙️ Config'!$B$6,IF($F32="Half Plot",'⚙️ Config'!$B$7,""))) | I32: =IF($B32="","",IF($F32="Full Plot",$G32*'⚙️ Config'!$B$6,IF($F32="Half Plot",($G32/'⚙️ Config'!$E$7)*'⚙️ Config'!$B$7,0))) | J32: =IF($B32="","",IF($F32="Full Plot",$G32*'⚙️ Config'!$C$6,IF($F32="Half Plot",($G32/'⚙️ Config'!$E$7)*'⚙️ Config'!$C$7,0))) | K32: =IF($B32="","",IFERROR($I32-$J32,0)) | M32: =IF($B32="","",IF($L32="","",IF($F32="Full Plot",$G32,IF($F32="Half Plot",$G32/'⚙️ Config'!$E$7,0))*IFERROR(VLOOKUP($L32,'⚙️ Config'!$A$11:$B$14,2,0),0))) | N32: =IF($B32="","",IFERROR($K32+IF($M32="",$K32*0,$M32),0)) | R32: =IF($B32="","",IFERROR(MAX($N32-$Q32,0),0))
A33: =IF($B33="","",ROW()-7) | H33: =IF($B33="","",IF($F33="Full Plot",'⚙️ Config'!$B$6,IF($F33="Half Plot",'⚙️ Config'!$B$7,""))) | I33: =IF($B33="","",IF($F33="Full Plot",$G33*'⚙️ Config'!$B$6,IF($F33="Half Plot",($G33/'⚙️ Config'!$E$7)*'⚙️ Config'!$B$7,0))) | J33: =IF($B33="","",IF($F33="Full Plot",$G33*'⚙️ Config'!$C$6,IF($F33="Half Plot",($G33/'⚙️ Config'!$E$7)*'⚙️ Config'!$C$7,0))) | K33: =IF($B33="","",IFERROR($I33-$J33,0)) | M33: =IF($B33="","",IF($L33="","",IF($F33="Full Plot",$G33,IF($F33="Half Plot",$G33/'⚙️ Config'!$E$7,0))*IFERROR(VLOOKUP($L33,'⚙️ Config'!$A$11:$B$14,2,0),0))) | N33: =IF($B33="","",IFERROR($K33+IF($M33="",$K33*0,$M33),0)) | R33: =IF($B33="","",IFERROR(MAX($N33-$Q33,0),0))
A34: =IF($B34="","",ROW()-7) | H34: =IF($B34="","",IF($F34="Full Plot",'⚙️ Config'!$B$6,IF($F34="Half Plot",'⚙️ Config'!$B$7,""))) | I34: =IF($B34="","",IF($F34="Full Plot",$G34*'⚙️ Config'!$B$6,IF($F34="Half Plot",($G34/'⚙️ Config'!$E$7)*'⚙️ Config'!$B$7,0))) | J34: =IF($B34="","",IF($F34="Full Plot",$G34*'⚙️ Config'!$C$6,IF($F34="Half Plot",($G34/'⚙️ Config'!$E$7)*'⚙️ Config'!$C$7,0))) | K34: =IF($B34="","",IFERROR($I34-$J34,0)) | M34: =IF($B34="","",IF($L34="","",IF($F34="Full Plot",$G34,IF($F34="Half Plot",$G34/'⚙️ Config'!$E$7,0))*IFERROR(VLOOKUP($L34,'⚙️ Config'!$A$11:$B$14,2,0),0))) | N34: =IF($B34="","",IFERROR($K34+IF($M34="",$K34*0,$M34),0)) | R34: =IF($B34="","",IFERROR(MAX($N34-$Q34,0),0))
A35: =IF($B35="","",ROW()-7) | H35: =IF($B35="","",IF($F35="Full Plot",'⚙️ Config'!$B$6,IF($F35="Half Plot",'⚙️ Config'!$B$7,""))) | I35: =IF($B35="","",IF($F35="Full Plot",$G35*'⚙️ Config'!$B$6,IF($F35="Half Plot",($G35/'⚙️ Config'!$E$7)*'⚙️ Config'!$B$7,0))) | J35: =IF($B35="","",IF($F35="Full Plot",$G35*'⚙️ Config'!$C$6,IF($F35="Half Plot",($G35/'⚙️ Config'!$E$7)*'⚙️ Config'!$C$7,0))) | K35: =IF($B35="","",IFERROR($I35-$J35,0)) | M35: =IF($B35="","",IF($L35="","",IF($F35="Full Plot",$G35,IF($F35="Half Plot",$G35/'⚙️ Config'!$E$7,0))*IFERROR(VLOOKUP($L35,'⚙️ Config'!$A$11:$B$14,2,0),0))) | N35: =IF($B35="","",IFERROR($K35+IF($M35="",$K35*0,$M35),0)) | R35: =IF($B35="","",IFERROR(MAX($N35-$Q35,0),0))
A36: =IF($B36="","",ROW()-7) | H36: =IF($B36="","",IF($F36="Full Plot",'⚙️ Config'!$B$6,IF($F36="Half Plot",'⚙️ Config'!$B$7,""))) | I36: =IF($B36="","",IF($F36="Full Plot",$G36*'⚙️ Config'!$B$6,IF($F36="Half Plot",($G36/'⚙️ Config'!$E$7)*'⚙️ Config'!$B$7,0))) | J36: =IF($B36="","",IF($F36="Full Plot",$G36*'⚙️ Config'!$C$6,IF($F36="Half Plot",($G36/'⚙️ Config'!$E$7)*'⚙️ Config'!$C$7,0))) | K36: =IF($B36="","",IFERROR($I36-$J36,0)) | M36: =IF($B36="","",IF($L36="","",IF($F36="Full Plot",$G36,IF($F36="Half Plot",$G36/'⚙️ Config'!$E$7,0))*IFERROR(VLOOKUP($L36,'⚙️ Config'!$A$11:$B$14,2,0),0))) | N36: =IF($B36="","",IFERROR($K36+IF($M36="",$K36*0,$M36),0)) | R36: =IF($B36="","",IFERROR(MAX($N36-$Q36,0),0))
A37: =IF($B37="","",ROW()-7) | H37: =IF($B37="","",IF($F37="Full Plot",'⚙️ Config'!$B$6,IF($F37="Half Plot",'⚙️ Config'!$B$7,""))) | I37: =IF($B37="","",IF($F37="Full Plot",$G37*'⚙️ Config'!$B$6,IF($F37="Half Plot",($G37/'⚙️ Config'!$E$7)*'⚙️ Config'!$B$7,0))) | J37: =IF($B37="","",IF($F37="Full Plot",$G37*'⚙️ Config'!$C$6,IF($F37="Half Plot",($G37/'⚙️ Config'!$E$7)*'⚙️ Config'!$C$7,0))) | K37: =IF($B37="","",IFERROR($I37-$J37,0)) | M37: =IF($B37="","",IF($L37="","",IF($F37="Full Plot",$G37,IF($F37="Half Plot",$G37/'⚙️ Config'!$E$7,0))*IFERROR(VLOOKUP($L37,'⚙️ Config'!$A$11:$B$14,2,0),0))) | N37: =IF($B37="","",IFERROR($K37+IF($M37="",$K37*0,$M37),0)) | R37: =IF($B37="","",IFERROR(MAX($N37-$Q37,0),0))
A38: =IF($B38="","",ROW()-7) | H38: =IF($B38="","",IF($F38="Full Plot",'⚙️ Config'!$B$6,IF($F38="Half Plot",'⚙️ Config'!$B$7,""))) | I38: =IF($B38="","",IF($F38="Full Plot",$G38*'⚙️ Config'!$B$6,IF($F38="Half Plot",($G38/'⚙️ Config'!$E$7)*'⚙️ Config'!$B$7,0))) | J38: =IF($B38="","",IF($F38="Full Plot",$G38*'⚙️ Config'!$C$6,IF($F38="Half Plot",($G38/'⚙️ Config'!$E$7)*'⚙️ Config'!$C$7,0))) | K38: =IF($B38="","",IFERROR($I38-$J38,0)) | M38: =IF($B38="","",IF($L38="","",IF($F38="Full Plot",$G38,IF($F38="Half Plot",$G38/'⚙️ Config'!$E$7,0))*IFERROR(VLOOKUP($L38,'⚙️ Config'!$A$11:$B$14,2,0),0))) | N38: =IF($B38="","",IFERROR($K38+IF($M38="",$K38*0,$M38),0)) | R38: =IF($B38="","",IFERROR(MAX($N38-$Q38,0),0))
A39: =IF($B39="","",ROW()-7) | H39: =IF($B39="","",IF($F39="Full Plot",'⚙️ Config'!$B$6,IF($F39="Half Plot",'⚙️ Config'!$B$7,""))) | I39: =IF($B39="","",IF($F39="Full Plot",$G39*'⚙️ Config'!$B$6,IF($F39="Half Plot",($G39/'⚙️ Config'!$E$7)*'⚙️ Config'!$B$7,0))) | J39: =IF($B39="","",IF($F39="Full Plot",$G39*'⚙️ Config'!$C$6,IF($F39="Half Plot",($G39/'⚙️ Config'!$E$7)*'⚙️ Config'!$C$7,0))) | K39: =IF($B39="","",IFERROR($I39-$J39,0)) | M39: =IF($B39="","",IF($L39="","",IF($F39="Full Plot",$G39,IF($F39="Half Plot",$G39/'⚙️ Config'!$E$7,0))*IFERROR(VLOOKUP($L39,'⚙️ Config'!$A$11:$B$14,2,0),0))) | N39: =IF($B39="","",IFERROR($K39+IF($M39="",$K39*0,$M39),0)) | R39: =IF($B39="","",IFERROR(MAX($N39-$Q39,0),0))
A40: =IF($B40="","",ROW()-7) | H40: =IF($B40="","",IF($F40="Full Plot",'⚙️ Config'!$B$6,IF($F40="Half Plot",'⚙️ Config'!$B$7,""))) | I40: =IF($B40="","",IF($F40="Full Plot",$G40*'⚙️ Config'!$B$6,IF($F40="Half Plot",($G40/'⚙️ Config'!$E$7)*'⚙️ Config'!$B$7,0))) | J40: =IF($B40="","",IF($F40="Full Plot",$G40*'⚙️ Config'!$C$6,IF($F40="Half Plot",($G40/'⚙️ Config'!$E$7)*'⚙️ Config'!$C$7,0))) | K40: =IF($B40="","",IFERROR($I40-$J40,0)) | M40: =IF($B40="","",IF($L40="","",IF($F40="Full Plot",$G40,IF($F40="Half Plot",$G40/'⚙️ Config'!$E$7,0))*IFERROR(VLOOKUP($L40,'⚙️ Config'!$A$11:$B$14,2,0),0))) | N40: =IF($B40="","",IFERROR($K40+IF($M40="",$K40*0,$M40),0)) | R40: =IF($B40="","",IFERROR(MAX($N40-$Q40,0),0))
A41: =IF($B41="","",ROW()-7) | H41: =IF($B41="","",IF($F41="Full Plot",'⚙️ Config'!$B$6,IF($F41="Half Plot",'⚙️ Config'!$B$7,""))) | I41: =IF($B41="","",IF($F41="Full Plot",$G41*'⚙️ Config'!$B$6,IF($F41="Half Plot",($G41/'⚙️ Config'!$E$7)*'⚙️ Config'!$B$7,0))) | J41: =IF($B41="","",IF($F41="Full Plot",$G41*'⚙️ Config'!$C$6,IF($F41="Half Plot",($G41/'⚙️ Config'!$E$7)*'⚙️ Config'!$C$7,0))) | K41: =IF($B41="","",IFERROR($I41-$J41,0)) | M41: =IF($B41="","",IF($L41="","",IF($F41="Full Plot",$G41,IF($F41="Half Plot",$G41/'⚙️ Config'!$E$7,0))*IFERROR(VLOOKUP($L41,'⚙️ Config'!$A$11:$B$14,2,0),0))) | N41: =IF($B41="","",IFERROR($K41+IF($M41="",$K41*0,$M41),0)) | R41: =IF($B41="","",IFERROR(MAX($N41-$Q41,0),0))
...

Sheet 📊 Dashboard
A1: 📊 MANAGEMENT DASHBOARD — TRULANDER JSF LIMITED | ROYAL PALM ENCLAVE
A2: All figures auto-calculated from Pipeline · Personal target: 2 plots/month · Job target: 1 plot/month
B4: GRAND TOTAL PIPELINE | D4: TOTAL COLLECTED | F4: TOTAL OUTSTANDING | H4: TOTAL INTEREST | J4: vs MONTHLY TARGET
B5: =SUM('💼 Pipeline'!N8:N91) -> 694500 | D5: =SUM('💼 Pipeline'!Q8:Q91) -> 0 | F5: =SUM('💼 Pipeline'!R8:R91) -> 694500 | H5: =SUM('💼 Pipeline'!M8:M91) -> 34500 | J5: =IFERROR(SUM('💼 Pipeline'!Q8:Q91)/'⚙️ Config'!$B$19,0) -> 0
B6: GHS | D6: GHS | F6: GHS | H6: GHS | J6: achieved
B8: TOTAL LEADS | D8: JOB TARGET | F8: PERSONAL TARGET | H8: FULL PLOTS | J8: SITE VISITS
B9: =COUNTA('💼 Pipeline'!B8:B91) -> 9 | D9: ='⚙️ Config'!$B$17 -> 1 | F9: ='⚙️ Config'!$B$18 -> 2 | H9: =COUNTIF('💼 Pipeline'!F8:F91,"Full Plot") -> 7 | J9: =COUNTIF('💼 Pipeline'!O8:O91,"Yes") -> 2
B10: leads | D10: plot/month | F10: plot/month | H10: clients | J10: done
A12: STAGE BREAKDOWN
B13: Stage | D13: Count | F13: Net Total (GHS) | H13: Grand Total (GHS) | J13: % of Pipeline
B14: Prospecting | D14: =COUNTIF('💼 Pipeline'!E8:E91,"Prospecting") -> 2 | F14: =SUMIF('💼 Pipeline'!E8:E91,"Prospecting",'💼 Pipeline'!K8:K91) -> 80000 | H14: =SUMIF('💼 Pipeline'!E8:E91,"Prospecting",'💼 Pipeline'!N8:N91) -> 84500 | J14: =IFERROR(SUMIF('💼 Pipeline'!E8:E91,"Prospecting",'💼 Pipeline'!N8:N91)/SUM('💼 Pipeline'!N8:N91),0) -> 0.12167027
B15: Discovery | D15: =COUNTIF('💼 Pipeline'!E8:E91,"Discovery") -> 2 | F15: =SUMIF('💼 Pipeline'!E8:E91,"Discovery",'💼 Pipeline'!K8:K91) -> 160000 | H15: =SUMIF('💼 Pipeline'!E8:E91,"Discovery",'💼 Pipeline'!N8:N91) -> 164500 | J15: =IFERROR(SUMIF('💼 Pipeline'!E8:E91,"Discovery",'💼 Pipeline'!N8:N91)/SUM('💼 Pipeline'!N8:N91),0) -> 0.23686105
B16: Qualified | D16: =COUNTIF('💼 Pipeline'!E8:E91,"Qualified") -> 1 | F16: =SUMIF('💼 Pipeline'!E8:E91,"Qualified",'💼 Pipeline'!K8:K91) -> 240000 | H16: =SUMIF('💼 Pipeline'!E8:E91,"Qualified",'💼 Pipeline'!N8:N91) -> 258000 | J16: =IFERROR(SUMIF('💼 Pipeline'!E8:E91,"Qualified",'💼 Pipeline'!N8:N91)/SUM('💼 Pipeline'!N8:N91),0) -> 0.37149028
B17: Proposal | D17: =COUNTIF('💼 Pipeline'!E8:E91,"Proposal") -> 0 | F17: =SUMIF('💼 Pipeline'!E8:E91,"Proposal",'💼 Pipeline'!K8:K91) -> 0 | H17: =SUMIF('💼 Pipeline'!E8:E91,"Proposal",'💼 Pipeline'!N8:N91) -> 0 | J17: =IFERROR(SUMIF('💼 Pipeline'!E8:E91,"Proposal",'💼 Pipeline'!N8:N91)/SUM('💼 Pipeline'!N8:N91),0) -> 0
B18: Negotiation | D18: =COUNTIF('💼 Pipeline'!E8:E91,"Negotiation") -> 4 | F18: =SUMIF('💼 Pipeline'!E8:E91,"Negotiation",'💼 Pipeline'!K8:K91) -> 180000 | H18: =SUMIF('💼 Pipeline'!E8:E91,"Negotiation",'💼 Pipeline'!N8:N91) -> 187500 | J18: =IFERROR(SUMIF('💼 Pipeline'!E8:E91,"Negotiation",'💼 Pipeline'!N8:N91)/SUM('💼 Pipeline'!N8:N91),0) -> 0.2699784
B19: Closed-Won | D19: =COUNTIF('💼 Pipeline'!E8:E91,"Closed-Won") -> 0 | F19: =SUMIF('💼 Pipeline'!E8:E91,"Closed-Won",'💼 Pipeline'!K8:K91) -> 0 | H19: =SUMIF('💼 Pipeline'!E8:E91,"Closed-Won",'💼 Pipeline'!N8:N91) -> 0 | J19: =IFERROR(SUMIF('💼 Pipeline'!E8:E91,"Closed-Won",'💼 Pipeline'!N8:N91)/SUM('💼 Pipeline'!N8:N91),0) -> 0
B20: Closed-Lost | D20: =COUNTIF('💼 Pipeline'!E8:E91,"Closed-Lost") -> 0 | F20: =SUMIF('💼 Pipeline'!E8:E91,"Closed-Lost",'💼 Pipeline'!K8:K91) -> 0 | H20: =SUMIF('💼 Pipeline'!E8:E91,"Closed-Lost",'💼 Pipeline'!N8:N91) -> 0 | J20: =IFERROR(SUMIF('💼 Pipeline'!E8:E91,"Closed-Lost",'💼 Pipeline'!N8:N91)/SUM('💼 Pipeline'!N8:N91),0) -> 0
A22: PRIORITY BREAKDOWN
B23: Priority | D23: Count | F23: Grand Total (GHS) | H23: Collected (GHS) | J23: Balance (GHS)
B24: High | D24: =COUNTIF('💼 Pipeline'!P8:P91,"High") -> 1 | F24: =SUMIF('💼 Pipeline'!P8:P91,"High",'💼 Pipeline'!N8:N91) -> 258000 | H24: =SUMIF('💼 Pipeline'!P8:P91,"High",'💼 Pipeline'!Q8:Q91) -> 0 | J24: =SUMIF('💼 Pipeline'!P8:P91,"High",'💼 Pipeline'!R8:R91) -> 258000
B25: Medium | D25: =COUNTIF('💼 Pipeline'!P8:P91,"Medium") -> 5 | F25: =SUMIF('💼 Pipeline'!P8:P91,"Medium",'💼 Pipeline'!N8:N91) -> 230500 | H25: =SUMIF('💼 Pipeline'!P8:P91,"Medium",'💼 Pipeline'!Q8:Q91) -> 0 | J25: =SUMIF('💼 Pipeline'!P8:P91,"Medium",'💼 Pipeline'!R8:R91) -> 230500
B26: Low | D26: =COUNTIF('💼 Pipeline'!P8:P91,"Low") -> 3 | F26: =SUMIF('💼 Pipeline'!P8:P91,"Low",'💼 Pipeline'!N8:N91) -> 206000 | H26: =SUMIF('💼 Pipeline'!P8:P91,"Low",'💼 Pipeline'!Q8:Q91) -> 0 | J26: =SUMIF('💼 Pipeline'!P8:P91,"Low",'💼 Pipeline'!R8:R91) -> 206000
A28: SALES TARGET PROGRESS
B29: =IFERROR("COLLECTED: GHS "&TEXT(SUM('💼 Pipeline'!Q8:Q91),"#,##0")&" of GHS "&TEXT('⚙️ Config'!$B$19,"#,##0")&" target ["&TEXT(IFERROR(SUM('💼 Pipeline'!Q8:Q91)/'⚙️ Config'!$B$19,0),"0.0%")&" achieved]","") -> COLLECTED: GHS 0 of GHS 96,000 target [0.0% achieved]
B30: =IFERROR("PIPELINE: GHS "&TEXT(SUM('💼 Pipeline'!N8:N91),"#,##0")&" | Outstanding: GHS "&TEXT(SUM('💼 Pipeline'!R8:R91),"#,##0")&" | Total leads: "&TEXT(COUNTA('💼 Pipeline'!B8:B91),"0"),"") -> PIPELINE: GHS 694,500 | Outstanding: GHS 694,500 | Total leads: 9
B31: =IFERROR("PERSONAL TARGET: "&TEXT('⚙️ Config'!$B$18,"0")&" plots/month | JOB TARGET: "&TEXT('⚙️ Config'!$B$17,"0")&" plot/month | Personal goal GHS: "&TEXT('⚙️ Config'!$B$19*'⚙️ Config'!$B$18,"#,##0"),"") -> PERSONAL TARGET: 2 plots/month | JOB TARGET: 1 plot/month | Personal goal GHS: 192,000
A32: TRULANDER JSF LIMITED | Royal Palm Enclave, Tsopoli | Confidential — Management Use Only

Sheet 🎯 Monthly Close
A1: 🎯 MONTHLY CLOSE TRACKER — ROYAL PALM ENCLAVE
A2: Type client name in Lead Name column → Grand Total, Contact & Plot auto-populate from Pipeline · pw: JSF2026
A4: ◀ APRIL 2026 ▶ Status: Open | Add clients below who closed or are being targeted this month
A5: TARGETED | C5: CLOSED-WON | E5: TOTAL CLOSED (GHS) | G5: COLLECTED (GHS) | I5: BALANCE (GHS) | K5: MONTH STATUS
A6: =COUNTA(B7:B21) -> 3 | C6: =COUNTIF(J7:J21,"Closed-Won") -> 0 | E6: =SUMIF(J7:J21,"Closed-Won",G7:G21) -> 0 | G6: =SUM(G7:G21) -> 0 | I6: =SUM(H7:H21) -> 0 | K6: Open
A7: # | B7: Lead Name | C7: Contact | D7: Plot Type | E7: No. Plots | F7: Grand Total (GHS) | G7: Amt Paid (GHS) | H7: Balance (GHS) | I7: Close Date | J7: Status | K7: Notes
A8: =IF($B8="","",ROW()-7) -> 1 | B8: Damaris | C8: =IF($B8="","",IFERROR(VLOOKUP($B8,'💼 Pipeline'!$B$8:$C$91,2,0),"— not found —")) -> — not found — | D8: =IF($B8="","",IFERROR(VLOOKUP($B8,'💼 Pipeline'!$B$8:$G$91,6,0),"")) | E8: =IF($B8="","",IFERROR(VLOOKUP($B8,'💼 Pipeline'!$B$8:$H$91,7,0),"")) | F8: =IF($B8="","",IFERROR(VLOOKUP($B8,'💼 Pipeline'!$B$8:$N$91,13,0),"")) | G8: =IF($B8="","",IFERROR(VLOOKUP($B8,'💼 Pipeline'!$B$8:$Q$91,16,0),"")) | H8: =IF($B8="","",IFERROR(VLOOKUP($B8,'💼 Pipeline'!$B$8:$R$91,17,0),"")) | J8: In Progress
A9: =IF($B9="","",ROW()-7) -> 2 | B9: Suzzy Donntwi | C9: =IF($B9="","",IFERROR(VLOOKUP($B9,'💼 Pipeline'!$B$8:$C$91,2,0),"— not found —")) -> — not found — | D9: =IF($B9="","",IFERROR(VLOOKUP($B9,'💼 Pipeline'!$B$8:$G$91,6,0),"")) | E9: =IF($B9="","",IFERROR(VLOOKUP($B9,'💼 Pipeline'!$B$8:$H$91,7,0),"")) | F9: =IF($B9="","",IFERROR(VLOOKUP($B9,'💼 Pipeline'!$B$8:$N$91,13,0),"")) | G9: =IF($B9="","",IFERROR(VLOOKUP($B9,'💼 Pipeline'!$B$8:$Q$91,16,0),"")) | H9: =IF($B9="","",IFERROR(VLOOKUP($B9,'💼 Pipeline'!$B$8:$R$91,17,0),"")) | J9: In Progress
A10: =IF($B10="","",ROW()-7) | C10: =IF($B10="","",IFERROR(VLOOKUP($B10,'💼 Pipeline'!$B$8:$C$91,2,0),"— not found —")) | D10: =IF($B10="","",IFERROR(VLOOKUP($B10,'💼 Pipeline'!$B$8:$G$91,6,0),"")) | E10: =IF($B10="","",IFERROR(VLOOKUP($B10,'💼 Pipeline'!$B$8:$H$91,7,0),"")) | F10: =IF($B10="","",IFERROR(VLOOKUP($B10,'💼 Pipeline'!$B$8:$N$91,13,0),"")) | G10: =IF($B10="","",IFERROR(VLOOKUP($B10,'💼 Pipeline'!$B$8:$Q$91,16,0),"")) | H10: =IF($B10="","",IFERROR(VLOOKUP($B10,'💼 Pipeline'!$B$8:$R$91,17,0),"")) | J10: Targeted
A11: =IF($B11="","",ROW()-7) | C11: =IF($B11="","",IFERROR(VLOOKUP($B11,'💼 Pipeline'!$B$8:$C$91,2,0),"— not found —")) | D11: =IF($B11="","",IFERROR(VLOOKUP($B11,'💼 Pipeline'!$B$8:$G$91,6,0),"")) | E11: =IF($B11="","",IFERROR(VLOOKUP($B11,'💼 Pipeline'!$B$8:$H$91,7,0),"")) | F11: =IF($B11="","",IFERROR(VLOOKUP($B11,'💼 Pipeline'!$B$8:$N$91,13,0),"")) | G11: =IF($B11="","",IFERROR(VLOOKUP($B11,'💼 Pipeline'!$B$8:$Q$91,16,0),"")) | H11: =IF($B11="","",IFERROR(VLOOKUP($B11,'💼 Pipeline'!$B$8:$R$91,17,0),"")) | J11: Targeted
A12: =IF($B12="","",ROW()-7) | C12: =IF($B12="","",IFERROR(VLOOKUP($B12,'💼 Pipeline'!$B$8:$C$91,2,0),"— not found —")) | D12: =IF($B12="","",IFERROR(VLOOKUP($B12,'💼 Pipeline'!$B$8:$G$91,6,0),"")) | E12: =IF($B12="","",IFERROR(VLOOKUP($B12,'💼 Pipeline'!$B$8:$H$91,7,0),"")) | F12: =IF($B12="","",IFERROR(VLOOKUP($B12,'💼 Pipeline'!$B$8:$N$91,13,0),"")) | G12: =IF($B12="","",IFERROR(VLOOKUP($B12,'💼 Pipeline'!$B$8:$Q$91,16,0),"")) | H12: =IF($B12="","",IFERROR(VLOOKUP($B12,'💼 Pipeline'!$B$8:$R$91,17,0),"")) | J12: Targeted
A13: =IF($B13="","",ROW()-7) | C13: =IF($B13="","",IFERROR(VLOOKUP($B13,'💼 Pipeline'!$B$8:$C$91,2,0),"— not found —")) | D13: =IF($B13="","",IFERROR(VLOOKUP($B13,'💼 Pipeline'!$B$8:$G$91,6,0),"")) | E13: =IF($B13="","",IFERROR(VLOOKUP($B13,'💼 Pipeline'!$B$8:$H$91,7,0),"")) | F13: =IF($B13="","",IFERROR(VLOOKUP($B13,'💼 Pipeline'!$B$8:$N$91,13,0),"")) | G13: =IF($B13="","",IFERROR(VLOOKUP($B13,'💼 Pipeline'!$B$8:$Q$91,16,0),"")) | H13: =IF($B13="","",IFERROR(VLOOKUP($B13,'💼 Pipeline'!$B$8:$R$91,17,0),"")) | J13: Targeted
A14: =IF($B14="","",ROW()-7) | C14: =IF($B14="","",IFERROR(VLOOKUP($B14,'💼 Pipeline'!$B$8:$C$91,2,0),"— not found —")) | D14: =IF($B14="","",IFERROR(VLOOKUP($B14,'💼 Pipeline'!$B$8:$G$91,6,0),"")) | E14: =IF($B14="","",IFERROR(VLOOKUP($B14,'💼 Pipeline'!$B$8:$H$91,7,0),"")) | F14: =IF($B14="","",IFERROR(VLOOKUP($B14,'💼 Pipeline'!$B$8:$N$91,13,0),"")) | G14: =IF($B14="","",IFERROR(VLOOKUP($B14,'💼 Pipeline'!$B$8:$Q$91,16,0),"")) | H14: =IF($B14="","",IFERROR(VLOOKUP($B14,'💼 Pipeline'!$B$8:$R$91,17,0),""))
A15: =IF($B15="","",ROW()-7) | C15: =IF($B15="","",IFERROR(VLOOKUP($B15,'💼 Pipeline'!$B$8:$C$91,2,0),"— not found —")) | D15: =IF($B15="","",IFERROR(VLOOKUP($B15,'💼 Pipeline'!$B$8:$G$91,6,0),"")) | E15: =IF($B15="","",IFERROR(VLOOKUP($B15,'💼 Pipeline'!$B$8:$H$91,7,0),"")) | F15: =IF($B15="","",IFERROR(VLOOKUP($B15,'💼 Pipeline'!$B$8:$N$91,13,0),"")) | G15: =IF($B15="","",IFERROR(VLOOKUP($B15,'💼 Pipeline'!$B$8:$Q$91,16,0),"")) | H15: =IF($B15="","",IFERROR(VLOOKUP($B15,'💼 Pipeline'!$B$8:$R$91,17,0),""))
A16: =IF($B16="","",ROW()-7) | C16: =IF($B16="","",IFERROR(VLOOKUP($B16,'💼 Pipeline'!$B$8:$C$91,2,0),"— not found —")) | D16: =IF($B16="","",IFERROR(VLOOKUP($B16,'💼 Pipeline'!$B$8:$G$91,6,0),"")) | E16: =IF($B16="","",IFERROR(VLOOKUP($B16,'💼 Pipeline'!$B$8:$H$91,7,0),"")) | F16: =IF($B16="","",IFERROR(VLOOKUP($B16,'💼 Pipeline'!$B$8:$N$91,13,0),"")) | G16: =IF($B16="","",IFERROR(VLOOKUP($B16,'💼 Pipeline'!$B$8:$Q$91,16,0),"")) | H16: =IF($B16="","",IFERROR(VLOOKUP($B16,'💼 Pipeline'!$B$8:$R$91,17,0),""))
A17: =IF($B17="","",ROW()-7) | C17: =IF($B17="","",IFERROR(VLOOKUP($B17,'💼 Pipeline'!$B$8:$C$91,2,0),"— not found —")) | D17: =IF($B17="","",IFERROR(VLOOKUP($B17,'💼 Pipeline'!$B$8:$G$91,6,0),"")) | E17: =IF($B17="","",IFERROR(VLOOKUP($B17,'💼 Pipeline'!$B$8:$H$91,7,0),"")) | F17: =IF($B17="","",IFERROR(VLOOKUP($B17,'💼 Pipeline'!$B$8:$N$91,13,0),"")) | G17: =IF($B17="","",IFERROR(VLOOKUP($B17,'💼 Pipeline'!$B$8:$Q$91,16,0),"")) | H17: =IF($B17="","",IFERROR(VLOOKUP($B17,'💼 Pipeline'!$B$8:$R$91,17,0),""))
A18: =IF($B18="","",ROW()-7) | C18: =IF($B18="","",IFERROR(VLOOKUP($B18,'💼 Pipeline'!$B$8:$C$91,2,0),"— not found —")) | D18: =IF($B18="","",IFERROR(VLOOKUP($B18,'💼 Pipeline'!$B$8:$G$91,6,0),"")) | E18: =IF($B18="","",IFERROR(VLOOKUP($B18,'💼 Pipeline'!$B$8:$H$91,7,0),"")) | F18: =IF($B18="","",IFERROR(VLOOKUP($B18,'💼 Pipeline'!$B$8:$N$91,13,0),"")) | G18: =IF($B18="","",IFERROR(VLOOKUP($B18,'💼 Pipeline'!$B$8:$Q$91,16,0),"")) | H18: =IF($B18="","",IFERROR(VLOOKUP($B18,'💼 Pipeline'!$B$8:$R$91,17,0),""))
A19: =IF($B19="","",ROW()-7) | C19: =IF($B19="","",IFERROR(VLOOKUP($B19,'💼 Pipeline'!$B$8:$C$91,2,0),"— not found —")) | D19: =IF($B19="","",IFERROR(VLOOKUP($B19,'💼 Pipeline'!$B$8:$G$91,6,0),"")) | E19: =IF($B19="","",IFERROR(VLOOKUP($B19,'💼 Pipeline'!$B$8:$H$91,7,0),"")) | F19: =IF($B19="","",IFERROR(VLOOKUP($B19,'💼 Pipeline'!$B$8:$N$91,13,0),"")) | G19: =IF($B19="","",IFERROR(VLOOKUP($B19,'💼 Pipeline'!$B$8:$Q$91,16,0),"")) | H19: =IF($B19="","",IFERROR(VLOOKUP($B19,'💼 Pipeline'!$B$8:$R$91,17,0),""))
A20: =IF($B20="","",ROW()-7) | C20: =IF($B20="","",IFERROR(VLOOKUP($B20,'💼 Pipeline'!$B$8:$C$91,2,0),"— not found —")) | D20: =IF($B20="","",IFERROR(VLOOKUP($B20,'💼 Pipeline'!$B$8:$G$91,6,0),"")) | E20: =IF($B20="","",IFERROR(VLOOKUP($B20,'💼 Pipeline'!$B$8:$H$91,7,0),"")) | F20: =IF($B20="","",IFERROR(VLOOKUP($B20,'💼 Pipeline'!$B$8:$N$91,13,0),"")) | G20: =IF($B20="","",IFERROR(VLOOKUP($B20,'💼 Pipeline'!$B$8:$Q$91,16,0),"")) | H20: =IF($B20="","",IFERROR(VLOOKUP($B20,'💼 Pipeline'!$B$8:$R$91,17,0),""))
A21: =IF($B21="","",ROW()-7) | C21: =IF($B21="","",IFERROR(VLOOKUP($B21,'💼 Pipeline'!$B$8:$C$91,2,0),"— not found —")) | D21: =IF($B21="","",IFERROR(VLOOKUP($B21,'💼 Pipeline'!$B$8:$G$91,6,0),"")) | E21: =IF($B21="","",IFERROR(VLOOKUP($B21,'💼 Pipeline'!$B$8:$H$91,7,0),"")) | F21: =IF($B21="","",IFERROR(VLOOKUP($B21,'💼 Pipeline'!$B$8:$N$91,13,0),"")) | G21: =IF($B21="","",IFERROR(VLOOKUP($B21,'💼 Pipeline'!$B$8:$Q$91,16,0),"")) | H21: =IF($B21="","",IFERROR(VLOOKUP($B21,'💼 Pipeline'!$B$8:$R$91,17,0),""))
A22: =IF($B22="","",ROW()-7) | C22: =IF($B22="","",IFERROR(VLOOKUP($B22,'💼 Pipeline'!$B$8:$C$91,2,0),"— not found —")) | D22: =IF($B22="","",IFERROR(VLOOKUP($B22,'💼 Pipeline'!$B$8:$G$91,6,0),"")) | E22: =IF($B22="","",IFERROR(VLOOKUP($B22,'💼 Pipeline'!$B$8:$H$91,7,0),"")) | F22: =IF($B22="","",IFERROR(VLOOKUP($B22,'💼 Pipeline'!$B$8:$N$91,13,0),"")) | G22: =IF($B22="","",IFERROR(VLOOKUP($B22,'💼 Pipeline'!$B$8:$Q$91,16,0),"")) | H22: =IF($B22="","",IFERROR(VLOOKUP($B22,'💼 Pipeline'!$B$8:$R$91,17,0),""))
A23: ▲ END OF APRIL 2026 | To close this month: update Status dropdown to 'Closed-Won' or 'Closed-Lost' for each lead · Pipeline Trend updates automatically
A25: ◀ MAY 2026 ▶ Status: Open | Add clients below who closed or are being targeted this month
A26: TARGETED | C26: CLOSED-WON | E26: TOTAL CLOSED (GHS) | G26: COLLECTED (GHS) | I26: BALANCE (GHS) | K26: MONTH STATUS
A27: =COUNTA(B28:B42) -> 2 | C27: =COUNTIF(J28:J42,"Closed-Won") -> 0 | E27: =SUMIF(J28:J42,"Closed-Won",G28:G42) -> 0 | G27: =SUM(G28:G42) -> 0 | I27: =SUM(H28:H42) -> 0 | K27: Open
A28: # | B28: Lead Name | C28: Contact | D28: Plot Type | E28: No. Plots | F28: Grand Total (GHS) | G28: Amt Paid (GHS) | H28: Balance (GHS) | I28: Close Date | J28: Status | K28: Notes
A29: =IF($B29="","",ROW()-28) -> 1 | B29: Shauntrece | C29: =IF($B29="","",IFERROR(VLOOKUP($B29,'💼 Pipeline'!$B$8:$C$91,2,0),"— not found —")) -> — not found — | D29: =IF($B29="","",IFERROR(VLOOKUP($B29,'💼 Pipeline'!$B$8:$G$91,6,0),"")) | E29: =IF($B29="","",IFERROR(VLOOKUP($B29,'💼 Pipeline'!$B$8:$H$91,7,0),"")) | F29: =IF($B29="","",IFERROR(VLOOKUP($B29,'💼 Pipeline'!$B$8:$N$91,13,0),"")) | G29: =IF($B29="","",IFERROR(VLOOKUP($B29,'💼 Pipeline'!$B$8:$Q$91,16,0),"")) | H29: =IF($B29="","",IFERROR(VLOOKUP($B29,'💼 Pipeline'!$B$8:$R$91,17,0),""))
A30: =IF($B30="","",ROW()-28) | C30: =IF($B30="","",IFERROR(VLOOKUP($B30,'💼 Pipeline'!$B$8:$C$91,2,0),"— not found —")) | D30: =IF($B30="","",IFERROR(VLOOKUP($B30,'💼 Pipeline'!$B$8:$G$91,6,0),"")) | E30: =IF($B30="","",IFERROR(VLOOKUP($B30,'💼 Pipeline'!$B$8:$H$91,7,0),"")) | F30: =IF($B30="","",IFERROR(VLOOKUP($B30,'💼 Pipeline'!$B$8:$N$91,13,0),"")) | G30: =IF($B30="","",IFERROR(VLOOKUP($B30,'💼 Pipeline'!$B$8:$Q$91,16,0),"")) | H30: =IF($B30="","",IFERROR(VLOOKUP($B30,'💼 Pipeline'!$B$8:$R$91,17,0),""))
A31: =IF($B31="","",ROW()-28) | C31: =IF($B31="","",IFERROR(VLOOKUP($B31,'💼 Pipeline'!$B$8:$C$91,2,0),"— not found —")) | D31: =IF($B31="","",IFERROR(VLOOKUP($B31,'💼 Pipeline'!$B$8:$G$91,6,0),"")) | E31: =IF($B31="","",IFERROR(VLOOKUP($B31,'💼 Pipeline'!$B$8:$H$91,7,0),"")) | F31: =IF($B31="","",IFERROR(VLOOKUP($B31,'💼 Pipeline'!$B$8:$N$91,13,0),"")) | G31: =IF($B31="","",IFERROR(VLOOKUP($B31,'💼 Pipeline'!$B$8:$Q$91,16,0),"")) | H31: =IF($B31="","",IFERROR(VLOOKUP($B31,'💼 Pipeline'!$B$8:$R$91,17,0),""))
A32: =IF($B32="","",ROW()-28) | C32: =IF($B32="","",IFERROR(VLOOKUP($B32,'💼 Pipeline'!$B$8:$C$91,2,0),"— not found —")) | D32: =IF($B32="","",IFERROR(VLOOKUP($B32,'💼 Pipeline'!$B$8:$G$91,6,0),"")) | E32: =IF($B32="","",IFERROR(VLOOKUP($B32,'💼 Pipeline'!$B$8:$H$91,7,0),"")) | F32: =IF($B32="","",IFERROR(VLOOKUP($B32,'💼 Pipeline'!$B$8:$N$91,13,0),"")) | G32: =IF($B32="","",IFERROR(VLOOKUP($B32,'💼 Pipeline'!$B$8:$Q$91,16,0),"")) | H32: =IF($B32="","",IFERROR(VLOOKUP($B32,'💼 Pipeline'!$B$8:$R$91,17,0),""))
A33: =IF($B33="","",ROW()-28) | C33: =IF($B33="","",IFERROR(VLOOKUP($B33,'💼 Pipeline'!$B$8:$C$91,2,0),"— not found —")) | D33: =IF($B33="","",IFERROR(VLOOKUP($B33,'💼 Pipeline'!$B$8:$G$91,6,0),"")) | E33: =IF($B33="","",IFERROR(VLOOKUP($B33,'💼 Pipeline'!$B$8:$H$91,7,0),"")) | F33: =IF($B33="","",IFERROR(VLOOKUP($B33,'💼 Pipeline'!$B$8:$N$91,13,0),"")) | G33: =IF($B33="","",IFERROR(VLOOKUP($B33,'💼 Pipeline'!$B$8:$Q$91,16,0),"")) | H33: =IF($B33="","",IFERROR(VLOOKUP($B33,'💼 Pipeline'!$B$8:$R$91,17,0),""))
A34: =IF($B34="","",ROW()-28) | C34: =IF($B34="","",IFERROR(VLOOKUP($B34,'💼 Pipeline'!$B$8:$C$91,2,0),"— not found —")) | D34: =IF($B34="","",IFERROR(VLOOKUP($B34,'💼 Pipeline'!$B$8:$G$91,6,0),"")) | E34: =IF($B34="","",IFERROR(VLOOKUP($B34,'💼 Pipeline'!$B$8:$H$91,7,0),"")) | F34: =IF($B34="","",IFERROR(VLOOKUP($B34,'💼 Pipeline'!$B$8:$N$91,13,0),"")) | G34: =IF($B34="","",IFERROR(VLOOKUP($B34,'💼 Pipeline'!$B$8:$Q$91,16,0),"")) | H34: =IF($B34="","",IFERROR(VLOOKUP($B34,'💼 Pipeline'!$B$8:$R$91,17,0),""))
A35: =IF($B35="","",ROW()-28) | C35: =IF($B35="","",IFERROR(VLOOKUP($B35,'💼 Pipeline'!$B$8:$C$91,2,0),"— not found —")) | D35: =IF($B35="","",IFERROR(VLOOKUP($B35,'💼 Pipeline'!$B$8:$G$91,6,0),"")) | E35: =IF($B35="","",IFERROR(VLOOKUP($B35,'💼 Pipeline'!$B$8:$H$91,7,0),"")) | F35: =IF($B35="","",IFERROR(VLOOKUP($B35,'💼 Pipeline'!$B$8:$N$91,13,0),"")) | G35: =IF($B35="","",IFERROR(VLOOKUP($B35,'💼 Pipeline'!$B$8:$Q$91,16,0),"")) | H35: =IF($B35="","",IFERROR(VLOOKUP($B35,'💼 Pipeline'!$B$8:$R$91,17,0),""))
A36: =IF($B36="","",ROW()-28) | C36: =IF($B36="","",IFERROR(VLOOKUP($B36,'💼 Pipeline'!$B$8:$C$91,2,0),"— not found —")) | D36: =IF($B36="","",IFERROR(VLOOKUP($B36,'💼 Pipeline'!$B$8:$G$91,6,0),"")) | E36: =IF($B36="","",IFERROR(VLOOKUP($B36,'💼 Pipeline'!$B$8:$H$91,7,0),"")) | F36: =IF($B36="","",IFERROR(VLOOKUP($B36,'💼 Pipeline'!$B$8:$N$91,13,0),"")) | G36: =IF($B36="","",IFERROR(VLOOKUP($B36,'💼 Pipeline'!$B$8:$Q$91,16,0),"")) | H36: =IF($B36="","",IFERROR(VLOOKUP($B36,'💼 Pipeline'!$B$8:$R$91,17,0),""))
A37: =IF($B37="","",ROW()-28) | C37: =IF($B37="","",IFERROR(VLOOKUP($B37,'💼 Pipeline'!$B$8:$C$91,2,0),"— not found —")) | D37: =IF($B37="","",IFERROR(VLOOKUP($B37,'💼 Pipeline'!$B$8:$G$91,6,0),"")) | E37: =IF($B37="","",IFERROR(VLOOKUP($B37,'💼 Pipeline'!$B$8:$H$91,7,0),"")) | F37: =IF($B37="","",IFERROR(VLOOKUP($B37,'💼 Pipeline'!$B$8:$N$91,13,0),"")) | G37: =IF($B37="","",IFERROR(VLOOKUP($B37,'💼 Pipeline'!$B$8:$Q$91,16,0),"")) | H37: =IF($B37="","",IFERROR(VLOOKUP($B37,'💼 Pipeline'!$B$8:$R$91,17,0),""))
A38: =IF($B38="","",ROW()-28) | C38: =IF($B38="","",IFERROR(VLOOKUP($B38,'💼 Pipeline'!$B$8:$C$91,2,0),"— not found —")) | D38: =IF($B38="","",IFERROR(VLOOKUP($B38,'💼 Pipeline'!$B$8:$G$91,6,0),"")) | E38: =IF($B38="","",IFERROR(VLOOKUP($B38,'💼 Pipeline'!$B$8:$H$91,7,0),"")) | F38: =IF($B38="","",IFERROR(VLOOKUP($B38,'💼 Pipeline'!$B$8:$N$91,13,0),"")) | G38: =IF($B38="","",IFERROR(VLOOKUP($B38,'💼 Pipeline'!$B$8:$Q$91,16,0),"")) | H38: =IF($B38="","",IFERROR(VLOOKUP($B38,'💼 Pipeline'!$B$8:$R$91,17,0),""))
A39: =IF($B39="","",ROW()-28) | C39: =IF($B39="","",IFERROR(VLOOKUP($B39,'💼 Pipeline'!$B$8:$C$91,2,0),"— not found —")) | D39: =IF($B39="","",IFERROR(VLOOKUP($B39,'💼 Pipeline'!$B$8:$G$91,6,0),"")) | E39: =IF($B39="","",IFERROR(VLOOKUP($B39,'💼 Pipeline'!$B$8:$H$91,7,0),"")) | F39: =IF($B39="","",IFERROR(VLOOKUP($B39,'💼 Pipeline'!$B$8:$N$91,13,0),"")) | G39: =IF($B39="","",IFERROR(VLOOKUP($B39,'💼 Pipeline'!$B$8:$Q$91,16,0),"")) | H39: =IF($B39="","",IFERROR(VLOOKUP($B39,'💼 Pipeline'!$B$8:$R$91,17,0),""))
A40: =IF($B40="","",ROW()-28) | C40: =IF($B40="","",IFERROR(VLOOKUP($B40,'💼 Pipeline'!$B$8:$C$91,2,0),"— not found —")) | D40: =IF($B40="","",IFERROR(VLOOKUP($B40,'💼 Pipeline'!$B$8:$G$91,6,0),"")) | E40: =IF($B40="","",IFERROR(VLOOKUP($B40,'💼 Pipeline'!$B$8:$H$91,7,0),"")) | F40: =IF($B40="","",IFERROR(VLOOKUP($B40,'💼 Pipeline'!$B$8:$N$91,13,0),"")) | G40: =IF($B40="","",IFERROR(VLOOKUP($B40,'💼 Pipeline'!$B$8:$Q$91,16,0),"")) | H40: =IF($B40="","",IFERROR(VLOOKUP($B40,'💼 Pipeline'!$B$8:$R$91,17,0),""))
A41: =IF($B41="","",ROW()-28) | C41: =IF($B41="","",IFERROR(VLOOKUP($B41,'💼 Pipeline'!$B$8:$C$91,2,0),"— not found —")) | D41: =IF($B41="","",IFERROR(VLOOKUP($B41,'💼 Pipeline'!$B$8:$G$91,6,0),"")) | E41: =IF($B41="","",IFERROR(VLOOKUP($B41,'💼 Pipeline'!$B$8:$H$91,7,0),"")) | F41: =IF($B41="","",IFERROR(VLOOKUP($B41,'💼 Pipeline'!$B$8:$N$91,13,0),"")) | G41: =IF($B41="","",IFERROR(VLOOKUP($B41,'💼 Pipeline'!$B$8:$Q$91,16,0),"")) | H41: =IF($B41="","",IFERROR(VLOOKUP($B41,'💼 Pipeline'!$B$8:$R$91,17,0),""))
... A43: =IF($B43="","",ROW()-28) | C43: =IF($B43="","",IFERROR(VLOOKUP($B43,'💼 Pipeline'!$B$8:$C$91,2,0),"— not found —")) | D43: =IF($B43="","",IFERROR(VLOOKUP($B43,'💼 Pipeline'!$B$8:$G$91,6,0),"")) | E43: =IF($B43="","",IFERROR(VLOOKUP($B43,'💼 Pipeline'!$B$8:$H$91,7,0),"")) | F43: =IF($B43="","",IFERROR(VLOOKUP($B43,'💼 Pipeline'!$B$8:$N$91,13,0),"")) | G43: =IF($B43="","",IFERROR(VLOOKUP($B43,'💼 Pipeline'!$B$8:$Q$91,16,0),"")) | H43: =IF($B43="","",IFERROR(VLOOKUP($B43,'💼 Pipeline'!$B$8:$R$91,17,0),""))
...

Sheet 📝 Activity Log
A1: 📝 DAILY ACTIVITY LOG — TRULANDER JSF LIMITED
A2: Log every client interaction · Type client name → fill conversation details · Follow-up dates turn RED when overdue · Filter by name to see full history · pw: JSF2026
A4: TOTAL LOGS | C4: THIS WEEK | E4: PENDING STEPS | G4: OVERDUE | I4: SITE VISITS | K4: UNIQUE LEADS
A5: =COUNTA(B6:B250) -> 8 | C5: =COUNTIFS(B6:B250,">="&(TODAY()-WEEKDAY(TODAY(),2)+1),B6:B250,"<="&TODAY()) -> 0 | E5: =COUNTIF(L6:L250,"No") -> 1 | G5: =COUNTIFS(K6:K250,"<"&TODAY(),L6:L250,"No") -> 1 | I5: =COUNTIF(E6:E250,"Site Visit") -> 0 | K5: =IFERROR(SUMPRODUCT(1/COUNTIF(D6:D250,D6:D250)*(D6:D250<>"")),0) -> 0
A6: # | B6: Date | C6: Time | D6: Client Name | E6: Contact Method | F6: Duration | G6: Stage | H6: What Was Discussed | I6: Client Response / Outcome | J6: Next Step Agreed | K6: Follow-up Date | L6: Done?
A7: =IF($D7="","",ROW()-6) -> 1 | B7: 24.04.2026 | C7: 10:00am | D7: Mama Victoria | E7: Other | F7: 10 min | G7: Qualified | H7: She wanted to deposit 3000gh and deposit another 3000gh to secure the plot and pay the rest on 12 months | I7: Paid 3000gh, left to pay for the rest | J7: Follow up with rest of payments for deposit and balance | K7: 46117 | L7: Yes
A8: =IF($D8="","",ROW()-6) -> 2 | B8: 27.04.2026 | C8: 11:00am | D8: Kweku | E8: Call | F8: 15 mins | G8: Discovery | H8: Introduced Royal Palm Enclave, pricing and plot options and payment plan options | I8: Wants to engage with family, will reach out soon. Did not want to give when | J8: Follow up with calls as a form of check up | K8: 46117 | L8: Yes
A9: =IF($D9="","",ROW()-6) -> 3 | B9: 27.04.2026 | C9: 1:00pm | D9: Raymond | E9: Call | F9: 5 mins | G9: Discovery | H9: Property presentation made.Included location, pricing, and payment plans | I9: Wants to get back in June | J9: Follow up again May, 25 | K9: 46137 | L9: Yes
A10: =IF($D10="","",ROW()-6) -> 4 | B10: 06.05.2026 | C10: 10:52am | D10: Janet | E10: Call | F10: 7 mins | G10: Discovery | H10: Introduced Royal Palm Enclave, pricing and discussions on landmarks and major projects around site | I10: Wants to visit the office at her covenience. | J10: Follow up calls | K10: 46119 | L10: Yes
A11: =IF($D11="","",ROW()-6) -> 5 | B11: 06.05.2026 | C11: 11:57am | D11: Richard Kofi Boye | E11: Call | F11: 10 mins | G11: Prospecting | H11: Introduced Royal Palm Enclave, pricing and discussions on landmarks and major projects around site as well as the need to make deposit now since the promo ends this week | I11: Wants to visit site on Monday and wants to buy half plot | J11: Follow up with calls on site visit and arrangements | K11: 46120 | L11: No
A12: =IF($D12="","",ROW()-6) -> 6 | B12: 29.04.2026 | C12: 1:00pm | D12: Portia | E12: Call | F12: 5 mins | G12: Discovery | H12: Presentation of land made with promo discussed | I12: Interested in 2 plots. But asked toget back by 1st week of May | J12: Follow up with calls and quotations | K12: 46119 | L12: Yes
A13: =IF($D13="","",ROW()-6) -> 7 | B13: 07.05.2026 | C13: 5:42pm | D13: Esther Apedo | E13: WhatsApp | F13: 5 mins | G13: Prospecting | H13: She called for the confirmation of the prices | I13: Wants to visit office on 8th May, 2026 | J13: Send location to office for physical meet up | K13: 07.Apr-26 | L13: Yes
A14: =IF($D14="","",ROW()-6)
A15: =IF($D15="","",ROW()-6)
A16: =IF($D16="","",ROW()-6)
A17: =IF($D17="","",ROW()-6)
A18: =IF($D18="","",ROW()-6)
A19: =IF($D19="","",ROW()-6)
A20: =IF($D20="","",ROW()-6)
A21: =IF($D21="","",ROW()-6)
A22: =IF($D22="","",ROW()-6)
A23: =IF($D23="","",ROW()-6)
A24: =IF($D24="","",ROW()-6)
A25: =IF($D25="","",ROW()-6)
... A213: =IF($D213="","",ROW()-6)
A214: ➕ HOW TO LOG AN INTERACTION: Type date in col B · Time in col C · Client name in col D · Select method from dropdown · Fill discussion, outcome, next step · Enter follow-up date · Set Done = No → turns RED when overdue · Filter by client name (col D) to see full history · EACH ROW = ONE CONVERSATION | New day = new row

Sheet 📈 Trend
A1: 📈 PIPELINE TREND TRACKER — ROYAL PALM ENCLAVE
A2: Monthly pipeline snapshot — auto-calculated from Pipeline & Monthly Close · Chart shows pipeline movement over time
A4: ℹ️ HOW IT WORKS: At the end of each month, enter the month's closing snapshot in the data table below. The chart updates automatically to show the pipeline trend. Grand Total, Collected, and Outstanding are the three trend lines.
A5: Month | B5: Grand Total (GHS) | C5: Net Total (GHS) | D5: Collected (GHS) | E5: Outstanding (GHS) | F5: New Leads Added | G5: Plots Closed
A6: Jan 2026 | B6: 195000 | C6: 175000 | D6: 0 | E6: 195000 | F6: 5 | G6: 0
A7: Feb 2026 | B7: 295000 | C7: 265000 | D7: 0 | E7: 295000 | F7: 8 | G7: 0
A8: Mar 2026 | B8: 455000 | C8: 410000 | D8: 11000 | E8: 444000 | F8: 12 | G8: 0
A9: April 2026 | B9: =IFERROR(SUM('💼 Pipeline'!N8:N28),0) -> 694500 | C9: =IFERROR(SUM('💼 Pipeline'!K8:K28),0) -> 660000 | D9: =IFERROR(SUM('💼 Pipeline'!Q8:Q28),0) -> 0 | E9: =IFERROR(SUM('💼 Pipeline'!R8:R28),0) -> 694500 | F9: =COUNTA('💼 Pipeline'!B8:B28) -> 9 | G9: =COUNTIF('🎯 Monthly Close'!J8:J21,"Closed-Won") -> 0
A10: May 2026 | B10: =IFERROR(SUM('💼 Pipeline'!N52:N91),0) -> 0 | C10: =IFERROR(SUM('💼 Pipeline'!K52:K91),0) -> 0 | D10: =IFERROR(SUM('💼 Pipeline'!Q52:Q91),0) -> 0 | E10: =IFERROR(SUM('💼 Pipeline'!R52:R91),0) -> 0 | F10: =COUNTA('💼 Pipeline'!B52:B91) -> 0
A11: June 2026
A12: July 2026
A13: August 2026
A14: September 2026
A15: October 2026
A16: November 2026
A17: December 2026
A19: 📊 WHAT THE CHART SHOWS: Each line tracks GHS amounts per month. GRAND TOTAL = full pipeline value · COLLECTED = actual cash received (the key growth line) · OUTSTANDING = remaining balance. April & May auto-update from live Pipeline. Add historical or future months manually.

Sheet ⚙️ Config
A1: ⚙️ CONFIGURATION & PRICING — ROYAL PALM ENCLAVE
A2: Edit BLUE cells only · All changes reflect instantly in the pipeline · Do not edit grey cells
A4: PLOT PRICING & DISCOUNTS
A5: Plot Type | B5: List Price (GHS) | C5: Discount / Unit (GHS) | D5: Net Price (GHS) | E5: Unit | F5: Notes
A6: Full Plot | B6: 48000 | C6: 8000 | D6: =B6-C6 -> 40000 | E6: 1 | F6: Qty 1=one full plot, 2=two plots, etc.
A7: Half Plot | B7: 26500 | C7: 6500 | D7: =B7-C7 -> 20000 | E7: 0.5 | F7: Qty 0.5=one half plot, 1.0=two halves
A9: PAYMENT PLAN INTEREST RATES (per full-plot equivalent)
A10: Payment Plan | B10: Interest / Plot-Eq (GHS) | F10: Notes
A11: 3 Months | B11: 750 | C11: 3 equal monthly instalments
A12: 6 Months | B12: 1500 | C12: 6 equal monthly instalments
A13: 9 Months | B13: 2250 | C13: 9 equal monthly instalments
A14: 12 Months | B14: 3000 | C14: 12 equal monthly instalments
A16: SETTINGS & TARGETS
A17: Job Description Target (plots/month) | B17: 1 | F17: Official KPI — 1 plot per month
A18: Personal Target (plots/month) | B18: 2 | F18: Your personal goal — 2 plots per month
A19: Monthly Sales Target (GHS) | B19: 96000 | F19: Based on 1 full plot net value × target
A20: Active Promo / Season | B20: Year of the Landlord – Easter 2026
A21: Current Period | B21: April–May 2026
A22: Property | B22: Royal Palm Enclave, Tsopoli, Ghana
A23: Company | B23: Trulander JSF Limited
A49: CLIENT NAMES LIST (used for dropdowns in Monthly Close & Activity Log — do not edit)
A51: Kess
A52: Suzzy Donntwi
A53: Sly Tetteh
A54: Ernest Arthur
A55: Isaac Asare
A56: Amanda
A57: Sharon
A58: Coach Kay
A59: Kwao Quaye
A60: Mr. James
A61: Serwa
... A70: Mr. James II
